<?xml version="1.0"?>
<!-- Robot tipo triciclo con 3 grados de libertad en archivo URDF: 
    - 2 ruedas traseras para propulsion
    - 1 horquilla delantera para direccion rotacional
    - 1 rueda delantera libre  -->
<robot name="triciclo_test">

<!-- Definicion de colores para visualizacion en Rviz y Gazebo -->
<!-- Rojo para rueda delantera -->
  <material name="rojo"><color rgba="1 0 0 1"/></material> 
  <!-- Verde para rueda trasera izquierda -->
  <material name="verde"><color rgba="0 1 0 1"/></material> 
  <!-- Azul para rueda trasera derecha -->
  <material name="azul"><color rgba="0 0 1 1"/></material>   
  <!-- Gris para el chasis y horquilla -->
  <material name="gris"><color rgba="0.5 0.5 0.5 1"/></material> 

<!-- Chasis principal del robot: base en donde se conectan las ruedas y la horquilla, su forma define la estructura del robot -->
  <link name="base_link">
    <visual>
      <origin xyz="0 0 0.38"/>
      <geometry><box size="1.2 0.6 0.12"/></geometry>
      <material name="gris"/>
    </visual>
    <collision>
      <origin xyz="0 0 0.38"/>
      <geometry><box size="1.2 0.6 0.12"/></geometry>
    </collision>
    <inertial>
      <origin xyz="0 0 0.38"/>
      <mass value="5.0"/>
      <inertia ixx="0.1" iyy="0.1" izz="0.1" ixy="0" ixz="0" iyz="0"/>
    </inertial>
  </link>

<!-- Horquilla delantera en forma de U que permite la direccion: Se compone de  dos brazos verticales y una barra horizontal superior que los une. Esta horquilla rota con respecto del chasis mediante el joint "direccion"  -->
  <link name="horquilla">
<!-- Brazo vertical izquierdo -->
    <visual><origin xyz="0 0.07 0.115"/><geometry><box size="0.02 0.02 0.19"/></geometry><material name="gris"/></visual>
<!-- Brazo vertical derecho -->
    <visual><origin xyz="0 -0.07 0.115"/><geometry><box size="0.02 0.02 0.19"/></geometry><material name="gris"/></visual>
<!-- Barra horizontal superior que une los brazos -->
    <visual><origin xyz="0 0 0.213"/><geometry><box size="0.02 0.16 0.014"/></geometry><material name="gris"/></visual>
<!-- Colision brazo derecho --> 
    <collision><origin xyz="0 0.07 0.115"/><geometry><box size="0.02 0.02 0.19"/></geometry></collision>
<!-- Colision brazo izquierdo -->
    <collision><origin xyz="0 -0.07 0.115"/><geometry><box size="0.02 0.02 0.19"/></geometry></collision>
<!-- Colision barra superior -->   
    <collision><origin xyz="0 0 0.213"/><geometry><box size="0.02 0.16 0.014"/></geometry></collision>
<!-- Inertial horquilla -->    
    <inertial>
      <origin xyz="0 0 0.115"/>
      <mass value="1.0"/>
      <inertia ixx="0.01" iyy="0.01" izz="0.01" ixy="0" ixz="0" iyz="0"/>
    </inertial>
  </link>

<!-- Joint: Chasis → Horquilla (dirección): Articulacion tipo "revolute" que permite la rotacion de la horquilla respecto al chasis, su eje de rotacion esta en Z, el cual limita el giro entre -90° y 90°  -->
  <joint name="direccion" type="revolute">
    <parent link="base_link"/>
    <child link="horquilla"/>
    <origin xyz="0.6 0 0.10"/>
    <axis xyz="0 0 1"/>
    <limit lower="-1.57" upper="1.57" effort="10" velocity="1"/>
  </joint>

<!-- Plugin para dirección -->
  <gazebo>
    <plugin name="gz_ros_joint_velocity_cmd_direccion" filename="gz_ros_joint_velocity_controller.so">
      <joint_name>direccion</joint_name>
      <topic>/world/default/model/triciclo/joint/direccion/cmd_vel</topic>
      <param name="gain">10.0</param>
    </plugin>
  </gazebo>

<!-- Rueda delantera: esta conectada a la horquilla, gira libremente  -->
  <link name="rueda_delantera">
    <visual><origin xyz="0 0 0" rpy="1.5708 0 0"/><geometry><cylinder radius="0.15" length="0.1"/></geometry><material name="rojo"/></visual>
    <collision>
      <origin xyz="0 0 0" rpy="1.5708 0 0"/>
      <geometry><cylinder radius="0.15" length="0.1"/></geometry>
      <surface>
        <friction>
          <ode>
            <mu>1.0</mu>
            <mu2>1.0</mu2>
          </ode>
        </friction>
      </surface>
    </collision>
    <inertial>
      <origin xyz="0 0 0"/>
      <mass value="0.5"/>
      <inertia ixx="0.01" iyy="0.01" izz="0.01" ixy="0" ixz="0" iyz="0"/>
    </inertial>
  </link>

<!-- Joint: Horquilla → Rueda delantera: conexion de la rueda delantera respecto a la horquilla -->
  <joint name="giro_rueda_delantera" type="continuous">
    <parent link="horquilla"/>
    <child link="rueda_delantera"/>
    <origin xyz="0 0 0.05"/>
    <axis xyz="0 1 0"/>
  </joint>

<!-- Rueda trasera izquierda: para propulsion, esta conectada al chasis -->
  <link name="rueda_izquierda">
    <visual><origin xyz="0 0 0" rpy="1.5708 0 0"/><geometry><cylinder radius="0.37" length="0.1"/></geometry><material name="verde"/></visual>
    <collision>
      <origin xyz="0 0 0" rpy="1.5708 0 0"/>
      <geometry><cylinder radius="0.37" length="0.1"/></geometry>
      <surface>
        <friction>
          <ode>
            <mu>1.5</mu>
            <mu2>1.5</mu2>
          </ode>
        </friction>
      </surface>
    </collision>
    <inertial>
      <origin xyz="0 0 0"/>
      <mass value="1.5"/>
      <inertia ixx="0.02" iyy="0.02" izz="0.02" ixy="0" ixz="0" iyz="0"/>
    </inertial>
  </link>

<!-- Joint: Chasis → Rueda trasera izquierda: joint de propulsion, gira libremente sobre el eje Y -->
  <joint name="propulsion_izq" type="continuous">
    <parent link="base_link"/>
    <child link="rueda_izquierda"/>
    <origin xyz="-0.5 0.35 0.37"/>
    <axis xyz="0 1 0"/>
  </joint>

  <!-- Plugin para rueda izquierda -->
  <gazebo>
    <plugin name="gz_ros_joint_velocity_cmd_izq" filename="gz_ros_joint_velocity_controller.so">
      <joint_name>propulsion_izq</joint_name>
      <topic>/world/default/model/triciclo/joint/propulsion_izq/cmd_vel</topic>
      <param name="gain">10.0</param>
    </plugin>
  </gazebo>

<!-- Rueda trasera derecha: para propulsion, esta conectada al chasis -->
  <link name="rueda_derecha">
    <visual><origin xyz="0 0 0" rpy="1.5708 0 0"/><geometry><cylinder radius="0.37" length="0.1"/></geometry><material name="azul"/></visual>
    <collision>
      <origin xyz="0 0 0" rpy="1.5708 0 0"/>
      <geometry><cylinder radius="0.37" length="0.1"/></geometry>
      <surface>
        <friction>
          <ode>
            <mu>1.5</mu>
            <mu2>1.5</mu2>
          </ode>
        </friction>
      </surface>
    </collision>
    <inertial>
      <origin xyz="0 0 0"/>
      <mass value="1.5"/>
      <inertia ixx="0.02" iyy="0.02" izz="0.02" ixy="0" ixz="0" iyz="0"/>
    </inertial>
  </link>

<!-- Joint: Chasis → Rueda trasera derecha: joint de propulsion, gira libremente sobre el eje Y -->
  <joint name="propulsion_der" type="continuous">
    <parent link="base_link"/>
    <child link="rueda_derecha"/>
    <origin xyz="-0.5 -0.35 0.37"/>
    <axis xyz="0 1 0"/>
  </joint>

  <!-- Plugin para rueda derecha -->
  <gazebo>
    <plugin name="gz_ros_joint_velocity_cmd_der" filename="gz_ros_joint_velocity_controller.so">
      <joint_name>propulsion_der</joint_name>
      <topic>/world/default/model/triciclo/joint/propulsion_der/cmd_vel</topic>
      <param name="gain">10.0</param>
    </plugin>
  </gazebo>

</robot>

