<?xml version="1.0"?>
<robot name="triciclo_test">

  <!-- Materiales -->
  <material name="rojo"><color rgba="1 0 0 1"/></material>  
  <material name="verde"><color rgba="0 1 0 1"/></material> 
  <material name="azul"><color rgba="0 0 1 1"/></material>    
  <material name="gris"><color rgba="0.5 0.5 0.5 1"/></material> 

  <!-- === CHASIS === -->
  <link name="base_link">
    <visual>
      <origin xyz="0 0 0.38"/>
      <geometry><box size="1.2 0.6 0.12"/></geometry>
      <material name="gris"/>
    </visual>
    <collision>
      <origin xyz="0 0 0.38"/>
      <geometry><box size="1.2 0.6 0.12"/></geometry>
    </collision>
    <inertial>
      <origin xyz="0 0 0.38"/>
      <mass value="5.0"/>
      <inertia ixx="0.1" iyy="0.1" izz="0.1" ixy="0" ixz="0" iyz="0"/>
    </inertial>
  </link>

  <!-- === HORQUILLA === -->
  <link name="horquilla">
    <visual><origin xyz="0 0.07 0.115"/><geometry><box size="0.02 0.02 0.19"/></geometry><material name="gris"/></visual>
    <visual><origin xyz="0 -0.07 0.115"/><geometry><box size="0.02 0.02 0.19"/></geometry><material name="gris"/></visual>
    <visual><origin xyz="0 0 0.213"/><geometry><box size="0.02 0.16 0.014"/></geometry><material name="gris"/></visual>
    <collision><origin xyz="0 0.07 0.115"/><geometry><box size="0.02 0.02 0.19"/></geometry></collision>
    <collision><origin xyz="0 -0.07 0.115"/><geometry><box size="0.02 0.02 0.19"/></geometry></collision>
    <collision><origin xyz="0 0 0.213"/><geometry><box size="0.02 0.16 0.014"/></geometry></collision>
    <inertial>
      <origin xyz="0 0 0.115"/>
      <mass value="1.0"/>
      <inertia ixx="0.01" iyy="0.01" izz="0.01" ixy="0" ixz="0" iyz="0"/>
    </inertial>
  </link>

  <joint name="direccion" type="revolute">
    <parent link="base_link"/>
    <child link="horquilla"/>
    <origin xyz="0.6 0 0.10"/>
    <axis xyz="0 0 1"/>
    <limit lower="-1.57" upper="1.57" effort="10" velocity="1"/>
  </joint>

  <!-- Plugin para dirección -->
  <gazebo>
    <plugin name="gz_ros_joint_velocity_cmd_direccion" filename="gz_ros_joint_velocity_controller.so">
      <joint_name>direccion</joint_name>
      <topic>/world/default/model/triciclo/joint/direccion/cmd_vel</topic>
      <param name="gain">10.0</param>
    </plugin>
  </gazebo>

  <!-- === RUEDA DELANTERA (pasiva) === -->
  <link name="rueda_delantera">
    <visual><origin xyz="0 0 0" rpy="1.5708 0 0"/><geometry><cylinder radius="0.15" length="0.1"/></geometry><material name="rojo"/></visual>
    <collision>
      <origin xyz="0 0 0" rpy="1.5708 0 0"/>
      <geometry><cylinder radius="0.15" length="0.1"/></geometry>
      <surface>
        <friction>
          <ode>
            <mu>1.0</mu>
            <mu2>1.0</mu2>
          </ode>
        </friction>
      </surface>
    </collision>
    <inertial>
      <origin xyz="0 0 0"/>
      <mass value="0.5"/>
      <inertia ixx="0.01" iyy="0.01" izz="0.01" ixy="0" ixz="0" iyz="0"/>
    </inertial>
  </link>

  <joint name="giro_rueda_delantera" type="continuous">
    <parent link="horquilla"/>
    <child link="rueda_delantera"/>
    <origin xyz="0 0 0.05"/>
    <axis xyz="0 1 0"/>
  </joint>

  <!-- === RUEDA IZQUIERDA === -->
  <link name="rueda_izquierda">
    <visual><origin xyz="0 0 0" rpy="1.5708 0 0"/><geometry><cylinder radius="0.37" length="0.1"/></geometry><material name="verde"/></visual>
    <collision>
      <origin xyz="0 0 0" rpy="1.5708 0 0"/>
      <geometry><cylinder radius="0.37" length="0.1"/></geometry>
      <surface>
        <friction>
          <ode>
            <mu>1.5</mu>
            <mu2>1.5</mu2>
          </ode>
        </friction>
      </surface>
    </collision>
    <inertial>
      <origin xyz="0 0 0"/>
      <mass value="1.5"/>
      <inertia ixx="0.02" iyy="0.02" izz="0.02" ixy="0" ixz="0" iyz="0"/>
    </inertial>
  </link>

  <joint name="propulsion_izq" type="continuous">
    <parent link="base_link"/>
    <child link="rueda_izquierda"/>
    <origin xyz="-0.5 0.35 0.37"/>
    <axis xyz="0 1 0"/>
  </joint>

  <!-- Plugin para rueda izquierda -->
  <gazebo>
    <plugin name="gz_ros_joint_velocity_cmd_izq" filename="gz_ros_joint_velocity_controller.so">
      <joint_name>propulsion_izq</joint_name>
      <topic>/world/default/model/triciclo/joint/propulsion_izq/cmd_vel</topic>
      <param name="gain">10.0</param>
    </plugin>
  </gazebo>

  <!-- === RUEDA DERECHA === -->
  <link name="rueda_derecha">
    <visual><origin xyz="0 0 0" rpy="1.5708 0 0"/><geometry><cylinder radius="0.37" length="0.1"/></geometry><material name="azul"/></visual>
    <collision>
      <origin xyz="0 0 0" rpy="1.5708 0 0"/>
      <geometry><cylinder radius="0.37" length="0.1"/></geometry>
      <surface>
        <friction>
          <ode>
            <mu>1.5</mu>
            <mu2>1.5</mu2>
          </ode>
        </friction>
      </surface>
    </collision>
    <inertial>
      <origin xyz="0 0 0"/>
      <mass value="1.5"/>
      <inertia ixx="0.02" iyy="0.02" izz="0.02" ixy="0" ixz="0" iyz="0"/>
    </inertial>
  </link>

  <joint name="propulsion_der" type="continuous">
    <parent link="base_link"/>
    <child link="rueda_derecha"/>
    <origin xyz="-0.5 -0.35 0.37"/>
    <axis xyz="0 1 0"/>
  </joint>

  <!-- Plugin para rueda derecha -->
  <gazebo>
    <plugin name="gz_ros_joint_velocity_cmd_der" filename="gz_ros_joint_velocity_controller.so">
      <joint_name>propulsion_der</joint_name>
      <topic>/world/default/model/triciclo/joint/propulsion_der/cmd_vel</topic>
      <param name="gain">10.0</param>
    </plugin>
  </gazebo>

</robot>

